Workbook

Sheet Sheet1
A1: Item | B1: Description | G1: Qty | H1: Rate | I1: SSP
D3: SUMMARY
C5: PROPOSED RESIDENCE
B7: Substructure | I7: 100333.65
B9: Walling and Frame | I9: 95598.4
B11: Roofing | I11: 52633
B13: Windows | I13: 42330
B15: Doors | I15: 49367
B17: External wall finishes | I17: 43407
B19: Internal wall finishes | I19: 51280
B21: Floor finishes | I21: 53174
B23: Ceiling finishes | I23: 30170
B25: Plubing & Drainage Installations | I25: 52611
B27: Electrical Installtion | I27: 37120.6
B30: PROPOSED RESIDENCE
B31: Summary
B33: TOTAL | I33: =SUM(I7:I27) -> 608024.65
B35: SUB-TOTAL 1
B37: ADD 2 % CONTINGENCIES | I37: =0.02*608024.65 -> 12160.493
B39: SUB-TOTAL 2 | I39: =SUM(I33:I37) -> 620185.14
B42: Grand Total | I42: 620185.14
A47: Item | B47: Description | F47: Unit | G47: Qty | H47: Rate (SSP) | I47: Amount (SSP)
B48: PROPOSED RESIDENCE
B49: ELEMENT A
B50: SUBSTRUCTURE
B51: (Up to and including groung slab)
A53: A | B53: Clear site of all grass, weeds, bushes, | F53: ha | G53: 0.2 | H53: 5 | I53: 1500
B54: shrubs and burn all arisings or cart away from
B55: site as directed and all leveling and grading
B56: site. | G56: .
A57: B | B57: Excavate oversite to reduce levels not | F57: m2 | G57: 93.75 | H57: 15 | I57: 1406.25
B58: exceeding 1.50m deep commencing from
B59: stripped level.
A61: C | B61: Excavate foundation trench including column | F61: m3 | G61: 78 | H61: 25 | I61: 1950
B62: bases no exceeding 1.50 m deep commencing
B63: from reduced level.
A65: D | B65: Return, fill in and ram selected excavated | F65: m3 | G65: 184 | H65: 20 | I65: 3680
B66: Materials around foundation.
A68: E | B68: Ditto but murram filling to make up levels | F68: m2 | G68: 184 | H68: 15 | I68: 2760
B69: under floors well consolidated in 75mm thick
...

Sheet Sheet2

Sheet Summary
A7: NANSANA BOQ
B10: Description | G10: Qty | H10: Rate | I10: Amount(Ushs)
D11: SUMMARY
C12: PROPOSED RESIDENCE
B14: Substructure | I14: 29533500
B16: Walling | I16: =Walling!I40 -> 11250500
B18: Roofing | I18: ='Roofing Sheets'!I33 -> 25837000
B20: Windows | I20: =Windows!I38 -> 7650000
B22: Doors | I22: =Doors!I41 -> 8498000
B24: External wall finishes | I24: ='External Wall finishes'!I12 -> 5008500
B26: Internal wall finishes | I26: ='Internal Wall finishes'!I11 -> 12171600
B28: Floor finishes | I28: ='Floor finishes'!I13 -> 11723000
B30: Ceiling finishes | I30: ='Ceiling Finishes'!I33 -> 15405500
B32: Plumbing & Drainage system | I32: =Plumbing!I18 -> 3500000
B34: Electrical Installtion | I34: =Electrical!I13 -> 3200000
B36: External works & Compound | I36: ='External works'!F10 -> 4500000
B42: Grand Total | I42: =SUM(I14:I36) -> 138277600

Sheet sub-structure 1
A2: Item | B2: Description | F2: Unit | G2: Qty | H2: Rate (Ushs) | I2: Amount (Ushs)
B3: PROPOSED RESIDENCE
B4: ELEMENT A
B5: SUBSTRUCTURE
B6: (Up to and including groung slab)
A8: A | B8: Clear site of all grass, weeds, bushes, | F8: sm | G8: 513 | H8: 500 | I8: =G8*H8 -> 256500
B9: shrubs and burn all arisings or cart away from
B10: site as directed and all leveling and grading
B11: site. | G11: .
A12: B | B12: Excavate oversite to reduce levels not | F12: sm | G12: 513 | H12: 2000 | I12: =G12*H12 -> 1026000
B13: exceeding 1.50m deep commencing from
B14: stripped level.
A16: C | B16: Excavate foundation trench including column | F16: cm | G16: 70 | H16: 6000 | I16: =G16*H16 -> 420000
B17: bases no exceeding 1.50 m deep commencing
B18: from reduced level.
A20: D | B20: Return, fill in and ram selected excavated | F20: item | G20: 25 | H20: 11000 | I20: =G20*H20 -> 275000
B21: Materials around foundation.
A24: F | B24: Load and wheel surplus excavated material | F24: cm | G24: 25 | H24: 6000 | I24: =G24*H24 -> 150000
B25: away from excavations, deposit in spoil heaps
B26: and later spread and level any where directed
B27: on site.
A29: G | B29: Allow for planking and strutting to uphold | F29: Item | G29: 1 | H29: 360000 | I29: =G29*H29 -> 360000
B30: sides of all foundation excavations.
A32: H | B32: Allow for keeping all foundation | F32: Item | G32: 1 | H32: 380000 | I32: =G32*H32 -> 380000
B33: excavation free from water.
A35: I | B35: 150mm thick bed of approved imported well | F35: sm | G35: 225 | H35: 12000 | I35: =G35*H35 -> 2700000
B36: spread levelled murram, rammed and consolidated in
B37: layers not exceeding 100mm to receive
B38: hardcore (measured separately).
B39: Total to be carried collection at end of element A | I39: =SUM(I8:I38) -> 5567500

Sheet sub-structure ii
B1: Substructure
A2: Item | B2: Description | F2: Unit | G2: Qty | H2: Rate(Ushs) | I2: Amount (Ushs)
B3: Plinth finishes:
A5: A | B5: 20mm thick cement and sand (1:4) rendering to | F5: sm | G5: 38 | H5: 8500 | I5: =G5*H5 -> 323000
B6: plinths externally.
A8: B | B8: Prepare and apply three coats bitumastic or | F8: sm | G8: 38 | H8: 15000 | I8: =G8*H8 -> 570000
B9: equal approved water resistant paint to render
B10: plinths externally.
B12: Splash apron
A13: C | B13: 75mm thick concrete (1:3:6) mix splash apron | F13: sm | G13: 62 | H13: 30000 | I13: =G13*H13 -> 1860000
B14: with all the necessary formwork.
A16: D | B16: 230mm th brick work laid in c/s mortar (1:3), in a suitable bond. | F16: sm | G16: 82 | H16: 30000 | I16: =G16*H16 -> 2460000
A19: E | B19: 25mm thick cement and sand (1:3) paving on | F19: sm | G19: 79 | H19: 25000 | I19: =G19*H19 -> 1975000
B20: splash apron finished with wooden float.
B22: Steel bar reinforcement to B.S 4449.1969:
A23: F | B23: 8mm Diameter bars in mild steel reinforcement. | F23: kg | G23: 140 | H23: 4000 | I23: =G23*H23 -> 560000
A25: G | B25: 16mm Diameter bars in High Tensile | F25: kg | G25: 80 | H25: 4000 | I25: =G25*H25 -> 320000
B26: reinforcement.
A28: H | B28: 12mm Diameter bars in High Tensile | F28: kg | G28: 85 | H28: 4000 | I28: =G28*H28 -> 340000
B29: reinforcement.
A31: I | B31: Sawn timber formwork to sides of columns in starter | F31: m2 | G31: 30 | H31: 16500 | I31: =G31*H31 -> 495000
B32: columns.
B33: Total to be carried collection at end of element A | I33: =SUM(I5:I32) -> 8903000

Sheet Walling
A1: Item | B1: Description | F1: Unit | G1: Qty | H1: Rate (Ushs) | I1: Amount (Ushs)
B2: ELEMENT B
B3: WALLING
B5: Precast concrete grade 20 as described:
A7: A | B7: 250 x 75mm cill, splya weathered, threaded and | F7: m | G7: 29 | H7: 25000 | I7: =G7*H7 -> 725000
B8: finished fair on all exposed surfaces bedded
B9: and jointed in cement and sand (1:4)mortor.
B11: Vibrated reinforcement insitu concrete grade 20
A12: B | B12: Beams. | F12: cm | G12: 5.8 | H12: 300000 | I12: =G12*H12 -> 1740000
A14: C | B14: Columns. | F14: cm | G14: 3.24 | H14: 300000 | I14: =G14*H14 -> 972000
B16: High yielded square twisted bar reinforcement to
B17: B.S. 4449: 1969 including:
A19: D | B19: 16mm bars for columns. | F19: kg | G19: 80 | H19: 4000 | I19: =G19*H19 -> 320000
A21: E | B21: 16mm bars for beams. | F21: kg | G21: 230 | H21: 4000 | I21: =G21*H21 -> 920000
B23: Mild steel bar reinforcment to BS.4449: 1969:
A24: F | B24: 8mm diameter bars. | F24: kg | G24: 160 | H24: 4000 | I24: =G24*H24 -> 640000
B26: SawnTimber Formwork:
A27: G | B27: Sawn formwork to sides and soffits of beam. | F27: sm | G27: 50 | H27: 16500 | I27: =G27*H27 -> 825000
A29: H | B29: Sawn formwork to sides columns. | F29: sm | G29: 29 | H29: 16500 | I29: =G29*H29 -> 478500
B31: Walling:
A32: I | B32: 230mm tick approved clay burnt or other brick | F32: sm | G32: 290 | H32: 15000 | I32: =G32*H32 -> 4350000
B33: walling in cement sand mortar (1:3)
A36: J | B36: Ditto 150mm thick wall. | F36: sm | G36: 32 | H36: 0 | I36: =G36*H36 -> 0
A38: K | B38: Ditto but raking cutting. | F38: m | G38: 28 | H38: 10000 | I38: =G38*H38 -> 280000
B40: Total to be carried collection at end of element B | I40: =SUM(I7:I39) -> 11250500

Sheet Roofing Sheets
A1: Item | B1: Description | F1: Unit | G1: Qty | H1: Rate | I1: Amount (Ushs)
B3: ELECMENT C
B4: ROOF CONSTRUCTION
B6: Roof construction, covering and pressure
B7: impregnate treated sawn approved timber.
A9: A | B9: 75 x 100mm wall plate bedded on and including | F9: m | G9: 35 | H9: 20000 | I9: =G9*H9 -> 700000
B10: 15mm cement-stand (1:3) blinding.
A11: B | B11: 50 x 150mm Principle Rafters. | F11: m | G11: 210 | H11: 12000 | I11: =G11*H11 -> 2520000
A12: C | B12: 50 x 100 Secondary rafters. | F12: m | G12: 212 | H12: 10000 | I12: =G12*H12 -> 2120000
A13: D | B13: 50 x 150 Tie beams. | F13: m | G13: 140 | H13: 12000 | I13: =G13*H13 -> 1680000
A14: E | B14: 50 x 100mm Struts and ties. | F14: m | G14: 150 | H14: 10000 | I14: =G14*H14 -> 1500000
A15: F | B15: 50 x 100mm Purlins. | F15: m | G15: 250 | H15: 10000 | I15: =G15*H15 -> 2500000
A16: G | B16: 38 x 38mm Battens. | F16: m | G16: 230 | H16: 7000 | I16: =G16*H16 -> 1610000
A17: H | B17: 50 x 200mm Ridge board. | F17: m | G17: 20 | H17: 20000 | I17: =G17*H17 -> 400000
B18: Plastic fascia
A19: I | B19: 25 x 250 plastic fascia and barge board. | F19: m | G19: 25 | H19: 25000 | I19: =G19*H19 -> 625000
B20: Roof covering in versatile sheets
A21: J | B21: 25 degree pitched roof covering of versatiles; | F21: sm | G21: 150 | H21: 50000 | I21: =G21*H21 -> 7500000
B22: fixed in accordance with manufacturer's
B23: instructions.
A24: K | B24: Chicken mesh fixed to rafter to hold polyethene | F24: sm | G24: 150 | H24: 25000 | I24: =G24*H24 -> 3750000
B25: sheeting.
A26: L | B26: Knot, prime. Stop and paint one undercoat and | F26: m | G26: 85 | H26: 5000 | I26: =G26*H26 -> 425000
B27: two gloss finishing coats of oil on wood surface
B28: 200-300 mm gith.
A29: M | B29: Valley piece. | F29: m | G29: 10 | H29: 15000 | I29: =G29*H29 -> 150000
A30: N | B30: Plastic Rain water gutter. | F30: m | G30: 7 | H30: 15000 | I30: =G30*H30 -> 105000
A31: O | B31: UPVC Down pipes. | F31: m | G31: 12 | H31: 21000 | I31: =G31*H31 -> 252000
B33: Total to be carried collection at end of element C | I33: =SUM(I9:I32) -> 25837000

Sheet Windows
A1: Item | B1: Description | F1: Unit | G1: Qty | H1: Rate | I1: Amount (Ushs)
B3: ELEMENT D
B4: WINDOWS
B6: Supply, assemble and fix purpose made
B7: aluminium, casement windows to the Engineer's
B8: details, constructed with 300mm permanent
B9: vent from standard sections delivered to site
B10: complete with and including all necessary
B11: glazing, hinges and catches, aluminium stay etc,
B12: with fixing lugs let into brickwork.
A16: D | B16: Window size 2300 x 3000mm high overall | F16: No. | G16: 1 | H16: 1200000 | I16: =G16*H16 -> 1200000
B17: complete with approved burglar proofing as per
B18: drawing.
A20: E | B20: Window size 1800 x 1500 mm high overall | F20: No. | G20: 9 | H20: 650000 | I20: =G20*H20 -> 5850000
B21: complete with approved burglar proofing
B22: as per the drawing.
A24: F | B24: Window size 600 x 900mm high overall | F24: No. | G24: 3 | H24: 200000 | I24: =G24*H24 -> 600000
B25: complete with approved burglar proofing as
B26: the drawing.
B38: Total to be carried collection at end of element D | I38: =SUM(I16:I37) -> 7650000

Sheet Doors
A1: Item | B1: Description | F1: Unit | G1: Qty | H1: Rate | I1: Amount (Ushs)
B3: ELEMENT E
B4: DOORS
B6: Prupose made doors constructed from
B7: Aluminium sections and Timber delivered to site
B8: complete and including all the necessary hinges,
B9: metallic spikes, lugs locking devices, etc.
A11: A | B11: Supply, assemble and fix casement door and | F11: No. | G11: 1 | H11: 500000 | I11: =G11*H11 -> 500000
B12: frame total overall size 900 x 2400mm high with
B13: steel louvred vet.
A14: D | B14: Supply, assemble and fix framed & ledged door | F14: No. | G14: 7 | H14: 650000 | I14: =G14*H14 -> 4550000
B15: and frame total overall size 900 x 2100mm high
B16: with vent over.
A17: E | B17: Frame size 900 x 2100mm high with 50 x 15mm door | F17: No. | G17: 7 | H17: 100000 | I17: =G17*H17 -> 700000
B18: stop.
A19: F | B19: Ditto but 750 x 2100 mm high. | F19: No. | G19: 3 | H19: 450000 | I19: =G19*H19 -> 1350000
B21: Flush door, 45mm thick solid core, faced with MR
B22: quality plywood foe painting, hardwood lipping
B23: to edges.
A24: G | B24: 900 x 2100mm. | F24: No. | I24: =G24*H24 -> 0
A25: H | B25: 750 x 2100mm. | F25: No. | I25: =G25*H25 -> 0
A26: I | B26: Prepare, prime and apply one undercoat and | F26: sm | G26: 6 | H26: 45000 | I26: =G26*H26 -> 270000
B27: two gloss finishing coats of oil paint on metal
B28: surface including opening edges (both sides
B29: measured flat).
A30: J | B30: Ditto but matt stain finish on wood surfaces | F30: sm | G30: 42 | H30: 6000 | I30: =G30*H30 -> 252000
A31: K | B31: Do but wood surface 200 - 300mm girth. | F31: m | G31: 42 | H31: 1000 | I31: =G31*H31 -> 42000
B32: Supply and assemble to timber following
B33: Ironmongery complete with all matching
B34: screws and keys.
A35: L | B35: 100 mm pressed steel butt hinges. | F35: prs | G35: 26 | H35: 12000 | I35: =G35*H35 -> 312000
A36: M | B36: Three-layer mortice lock as 'Union UK' or any | F36: No. | G36: 14 | H36: 15000 | I36: =G36*H36 -> 210000
B37: other equal approved complete with furniture.
A38: N | B38: Casement lock. | F38: No. | G38: 26 | H38: 12000 | I38: =G38*H38 -> 312000
A39: O | B39: Garage Door | F39: No.
B41: Total to be carried to summary at end of Element E | I41: =SUM(I11:I40) -> 8498000

Sheet External Wall finishes
A1: Item | B1: Description | F1: Unit | G1: Qty | H1: Rate | I1: Amount (Ushs)
B2: ELEMENT F
B3: EXTERNAL WALL FINISHES
B4: Cemment and sand (1:3):
A5: A | B5: 20mm th rendering to walls in two coats finished | F5: sm | G5: 215 | H5: 8900 | I5: =G5*H5 -> 1913500
B6: with a wooden float.
A7: B | B7: Burnt clay facing bricks to walls. | F7: sm | I7: =G7*H7 -> 0
A8: C | B8: Two coats of rough cast to rendered walls. | F8: sm | G8: 185 | H8: 3000 | I8: =G8*H8 -> 555000
A9: D | B9: Prepare and apply three coats of weatherguard | F9: sm | G9: 212 | H9: 10000 | I9: =G9*H9 -> 2120000
B10: emulsion paint on rough cast rendered walls.
A11: E | B11: Stone cladding as external render to walls. | F11: sm | G11: 21 | H11: 20000 | I11: =G11*H11 -> 420000
B12: Total to be carried to summary at end of Element F | I12: =SUM(I5:I11) -> 5008500

Sheet Internal Wall finishes
A1: Item | B1: Description | F1: Unit | G1: Qty | H1: Rate | I1: Amount (Ushs)
B2: ELEMENT G
B3: INTERNAL WALL FINISHES
B4: Cement Lime sand (1:2:9) as described:
A5: A | B5: 20 mm internal plaster in two walls, | F5: sm | G5: 580 | H5: 8100 | I5: =G5*H5 -> 4698000
B6: trovelled hard and smooth with steel float.
A7: B | B7: Ceramic wall tiles to walls. | F7: sm | G7: 46 | H7: 54000 | I7: =G7*H7 -> 2484000
A8: C | B8: Prepare and apply three coats of plastic | F8: sm | G8: 580 | H8: 8100 | I8: =G8*H8 -> 4698000
B9: emulsion paint on plastered walls internally.
A10: D | B10: Ditto but reveals. | F10: sm | G10: 36 | H10: 8100 | I10: =G10*H10 -> 291600
B11: Total to be carried to summary at end of Element G | I11: =SUM(I5:I10) -> 12171600

Sheet Floor finishes
A1: Item | B1: Description | F1: Unit | G1: Qty | H1: Rate | I1: Amount (Ushs)
B2: ELEMENT H
B3: FLOOR FINISHES
B4: Cement and Sand (1:3) as described:
A5: A | B5: 25mm th floor screed finish trowelled hard and | F5: sm | G5: 212 | H5: 9000 | I5: =G5*H5 -> 1908000
B6: smooth with steeltrowel.
A7: B | B7: Ceramic tile floor finishing. | F7: m2 | G7: 212 | H7: 30000 | I7: =G7*H7 -> 6360000
A8: C | B8: PVC tile floor finishing. | F8: m3 | G8: 37 | H8: 25000 | I8: =G8*H8 -> 925000
A9: D | B9: 20 x 100mm skirting with rounded top edge and | F9: m | G9: 460 | H9: 2500 | I9: =G9*H9 -> 1150000
B10: curved at junction with floor screed.
A11: E | B11: Prepare and apply three coats of gloss oil paint | F11: m | G11: 460 | H11: 3000 | I11: =G11*H11 -> 1380000
B12: on timber skirting 100 - 200 mm girth.
B13: Total to be carried to summary at end of Element H | I13: =SUM(I5:I12) -> 11723000

Sheet Ceiling Finishes
A1: Item | B1: Description | F1: Unit | G1: Qty | H1: Rate | I1: Amount (Ushs)
B3: ELEMENT I
B4: CEILING FINISHES
B6: Sawn cypress or other equal approved including
B7: suspension system: well seasoned: cell cured:
B8: Selected and kept clean:
A10: A | B10: 100 x 50mm ceiling battens at perimeter, plugged. | F10: m | G10: 460 | H10: 9000 | I10: =G10*H10 -> 4140000
A12: B | B12: Ceiling branderings, 75 x 50 mm members. | F12: m | G12: 380 | H12: 7000 | I12: =G12*H12 -> 2660000
A14: C | B14: 100 x 20mm wrot "cypress" or other approved | F14: m | G14: 270 | H14: 6000 | I14: =G14*H14 -> 1620000
B15: cornice.
A17: D | B17: 5mm th cement: sand mortar on metal lathe | F17: sm | G17: 190 | H17: 8700 | I17: =G17*H17 -> 1653000
B18: secret nailed to brandering
B19: (measured separately).
A21: E | B21: Supply and fix 600mm access penal with sides | F21: No. | G21: 1 | H21: 65000 | I21: =G21*H21 -> 65000
B22: cut levelled to 45 degrees and fixed on and
B23: including painting to all exposed surfaces.
A25: F | B25: Supply and apply three coats of plastic emulsion | F25: sm | G25: 215 | H25: 8500 | I25: =G25*H25 -> 1827500
B26: paint on metal lathe ceiling.
A28: G | B28: Ditto but cornice. | F28: m | G28: 270 | H28: 5000 | I28: =G28*H28 -> 1350000
A30: I | B30: Expanded Metal Lathe | F30: sm | G30: 190 | H30: 11000 | I30: =G30*H30 -> 2090000
B33: Total to be carried to summary at end of Element I | I33: =SUM(I4:I30) -> 15405500

Sheet Electrical
A1: Item | B1: Description | F1: Unit | G1: Qty | H1: Rate | I1: Amount (Ushs)
B2: ELEMENT J:ELECTRICAL INSTALLATIONS
A4: A | B4: Allow a provisional sum of U shs 9000,000 (Nine million Uganda Shillings for Electrical installations) | F4: Sum | H4: 3200000 | I4: =H4 -> 3200000
B13: Total to be carried to collection as and of element J | I13: =SUM(I4) -> 3200000

Sheet Plumbing
A1: Item | B1: Description | F1: Unit | G1: Qty | H1: Rate | I1: Amount (U shs)
B3: Allow for a provisional sum of U shs 6000,000 for Plumbing works | F3: Sum | H3: 6000000 | I3: =H3 -> 6000000
B18: Total to be carried to summary at end of Element K | I18: 3500000
A72: Item | B72: Description | F72: Unit | G72: Qty | H72: Rate | I72: SSP
B75: Plinth walling
B77: Brickwork in cement and sand mortor 1:3 mix,
B78: laid in suitable bond with 6 mm diameter mild
B79: steel strips laid horizontally every aternate wide.
A81: J | B81: 230 mm thick walling. | F81: m2 | G81: 82 | H81: 142 | I81: 11644
A83: K | B83: Horizontal: 230 mm wide. | F83: m | G83: 12 | H83: 35 | I83: 420
I86: =SUM(I25:L83) -> 12064
B87: Total to be carried collection at end of element A
B89: PROPOSED RESIDENCE

Sheet unwanted
A1: Item | B1: Description | F1: Unit | G1: Qty | H1: Rate | I1: SSP
A3: A | B3: 150 mm thick bed of approved imported | F3: m2 | G3: 235 | H3: 36 | I3: 8460
B4: hardcore well spread, levelled, rammed and
B5: consolidated in layers not excedding 100 mm,
B6: blinded with and including 500 mm thick of
B7: sand, well watered and rolled to receive
B8: concrete bed (measured separately).
A10: B | B10: Dig out any existing termite mount, destroy | F10: m2 | G10: 300 | H10: 3 | I10: 900
B11: queen and apply approved anti-termite spray
B12: to entire site.
A14: C | B14: 1000 Gauge diothene or other equal approved | F14: m2 | G14: 235 | H14: 13 | I14: 3055
B15: polyethene sheeting as damp proof
B16: membrane joints laid of blinded hardcore
B17: (measured separately) with welted joints
B18: and minimum 200 mm end and side laps.
B20: Plain Insitu concrete Grade 15:
A22: D | B22: Strip foundation. | F22: m3 | G22: 12 | H22: 930 | I22: 11160
A24: E | B24: 100 mm floor bed laid on blinded hardcore with | F24: m2 | G24: 285 | H24: 93 | I24: 21885
B25: steel wire fabric mesh reinforcement to
B26: B.S (measured separately).
A28: F | B28: 4483 Ref.A98 weighing 1.58kg/m2 in concrete | F28: m2 | G28: 235 | H28: 73 | I28: 17236
B29: floor bed with minimum 300 mm end and side
B30: laps.
B32: Swan framework:
A34: G | B34: Sides of foundation in trenches. | F34: m2 | G34: 23 | H34: 85 | I34: 1955
A36: H | B36: 25 x 150 mm softwood to edge slab. | F36: m | G36: 62 | H36: 47 | I36: 2914
B38: Vibrated Reinforcement Insitu Concrete Grade 20:
A40: I | B40: Column base. | F40: m3 | G40: 5 | H40: 1085 | I40: 5425

Sheet External works
A1: Item | B1: Description | C1: Unit | D1: Qty | E1: Rate | F1: Amount (Ushs)
A6: A | B6: Allow a provisinal sum of 5000,000 U g shs for Externalworks ( Including Man holes and Compund work) | C6: SUM | E6: 4500000 | F6: =E6 -> 4500000
F10: =F6 -> 4500000
