Workbook
Name _2.1Boholes_and_pump_Stations2: #REF!
Name _B100: #REF!
Name _B100: #REF!
Name _B100: #REF!
Name _B100: #REF!
Name _B100: #REF!
Name _B100000: #REF!
Name _B100000: #REF!
Name _B100000: #REF!
Name _B100000: #REF!
Name _B100000: #REF!
Name _B100000: #REF!
Name _B1000000: #REF!
Name _B1000000: #REF!
Name _B1000000: #REF!
Name _B1000000: #REF!
Name _B1000000: #REF!
Name _B1000000: #REF!
Name _B990000: #REF!
Name _B990000: #REF!
Name _B990000: #REF!
Name _B990000: #REF!
Name _B990000: #REF!
Name a: #REF!
Name aa: #REF!
Name aa: #REF!
Name aa: #REF!
Name aa: #REF!
Name aa: #REF!
Name AB: #REF!
Name AB: #REF!
Name AB: #REF!
Name AB: #REF!
Name AB: #REF!
Name ablution: #REF!
Name ablution: #REF!
Name ablution: #REF!
Name ablution: #REF!
Name ablution: #REF!
Name adaptors: #REF!
Name airvalves: #REF!
Name Anti_termite_treatment: #REF!
Name Anti_termite_treatment: #REF!
Name Anti_termite_treatment: #REF!
Name Anti_termite_treatment: #REF!
Name Anti_termite_treatment: #REF!
Name aqsww: #REF!
Name aqsww: #REF!
Name aqsww: #REF!
Name aqsww: #REF!
Name aqsww: #REF!
Name aserr: #REF!
Name aserr: #REF!
Name aserr: #REF!
Name aserr: #REF!
Name aserr: #REF!
Name Assumed_Yard_Connection_Growth_Rate: #REF!
Name b: #REF!
Name b: #REF!
Name b: #REF!

Sheet Cover Page 
B3: Republic of Uganda
B4: Uganda Police Force
B8: CONSTRUCTION OF THE PROPOSED POLICE CDAC BUILDING AT KIBULI
B14: ESTIMATE BILLS OF QUANTITIES (SCHEME DESIGN STAGE)
D25: FEBRUARY 2025

Sheet Fly Sht. Main Summary
B3: MAIN SUMMARY

Sheet Main Summary
B2: PROJECT: | D2: CONSTRUCTION OF THE PROPOSED POLICE CDAC BUILDING AT KIBULI
B3: EMPLOYER: | D3: UGANDA POLICE FORCE
B4: LOCATION:
B5: DATE: | D5: ='Cover Page '!D25 -> FEBRUARY 2025
B6: MAIN SUMMARY
B8: BILL NO. | D8: DESCRIPTION | F8: PAGE NO. | G8: AMOUNT (USHS.)
B12: 4 | D12: ELECTRICAL INSTALLATIONS | F12: ='Sum. Bill No.4'!C28 -> 4/S | G12: ='Sum. Bill No.4'!E27 -> 1168620150
B13: 5 | D13: MECHANICAL INSTALLATIONS | F13: ='Sum. Bill No.5'!C27 -> 5/S | G13: ='Sum. Bill No.5'!E26 -> 652532100
B14: 6 | D14: ='Sum. Bill No.6'!C5 -> FIRE FIGHTING INSTALLATIONS | F14: ='Sum. Bill No.6'!C27 -> 6/S | G14: ='Sum. Bill No.6'!E26 -> 395471000
B15: 7 | D15: HVAC INSTALLATIONS | F15: ='Sum. Bill No.7'!C25 -> 7/S | G15: ='Sum. Bill No.7'!E24 -> 1.2646556e+09
B16: 8 | D16: LIFT INSTALLATIONS | F16: ='Bill No.8 Lift Inst.'!C38 -> 8/S | G16: ='Bill No.8 Lift Inst.'!G37 -> 356900000
B17: 9 | D17: ICT INSTALLATIONS | F17: ='Sum. Bill No.9'!C25 -> 9/S | G17: ='Sum. Bill No.9'!E24 -> 430266500
D22: SUB-TOTAL 1 | G22: =SUM(G9:G21) -> 4.2684453e+09
D23: ADD: CONTINGENCIES | F23: 0.05 | G23: =G22*F23 -> 2.1342227e+08
D24: SUB-TOTAL 2 | G24: =SUM(G22:G23) -> 4.4818676e+09
D25: ADD: VAT | F25: 0.18 | G25: =G24*F25 -> 8.0673617e+08
D26: TOTAL COST | G26: =SUM(G24:G25) -> 5.2886037e+09 | J26: =G26/0.25 -> 2.1154415e+10
B28: …………………………………….……………… | E28: …………………….………………………. | J28: =J26/3670 -> 5764145.8
B29: Signature of Employer | E29: Signature of the Contractor
B31: Witness: ______________________________ | E31: Witness: ___________________________
B32: ______________________________ | E32: ___________________________
B33: ______________________________ | E33: ___________________________
B35: Date: ………………..……………….. | E35: Date: ………………………………...……….
E37: G/S

Sheet Fly Sht. Main Sum
B2: MAIN SUMMARY

Sheet Main Contract
B2: ITEM | C2: DESCRIPTION | D2: QTY | E2: UNIT | F2: RATE (US$.) | G2: AMOUNT (US$.)
C3: =#REF! -> #REF!
C4: APARTMENTS BLOCK
C5: ELEMENT NO.1
C6: SITE CLEARANCE AND EARTHWORKS
C7: DEMOLITIONS
C8: Carefully demolish and pull down to ground including grubbing up foundations of the following buildings; comprising of: galvanised iron sheet roof covering on existing roof structure, solid walls, concrete floor slab with and including all doors, windows, fittings, electrical and mechanical installations, and including all other existing sundries; allow for keeping andhanding over all salvaged materials to the project manager, or remove from site as directed; make good areas disturbed and remove debris arising from site
B9: A | C9: Building; (Gross floor area Approx. 251SM) | D9: 1 | E9: ITEM | F9: 1631.5 | G9: =F9*D9 -> 1631.5
B10: B | C10: Building; (Gross floor area Approx. 67SM) | D10: 1 | E10: ITEM | F10: 435.5 | G10: =F10*D10 -> 435.5
C11: SITE CLEARANCE
B12: C | C12: Clear site of all trees, bushes, shrubs and under growth including grubbing up roots and removing away from site | D12: 2355 | E12: SM | F12: 0.35 | G12: =F12*D12 -> 824.25
B13: D | C13: Excavate average 200mm deep to remove top soil: remove from site | D13: =D12 -> 2355 | E13: SM | F13: 0.65 | G13: =F13*D13 -> 1530.75
C14: EARTHWORKS
B15: E | C15: Mechanical excavation to reduce levels not exceeding 1.5m deep commencing from stripped level | D15: 3522 | E15: CM | F15: 1.64 | G15: =D15*F15 -> 5776.08
B16: F | C16: Ditto but 1.5 - 3.0 meters deep; | D16: =D15 -> 3522 | E16: CM | F16: 2.05 | G16: =D16*F16 -> 7220.1
C17: DESIGN AND INSTALLATION OF LATERAL SUPPORT
B18: G | C18: Design and install lateral support to the exposed vertical faces of excavation average 3.0m deep and 50m long in confined space from foundations to ground level; all to project manager's approval; | D18: 1 | E18: ITEM | F18: 540 | G18: =F18*D18 -> 540
B19: H | C19: Allow for keeping the whole of the excavation free from general water. | D19: 1 | E19: ITEM | F19: 410 | G19: =F19*D19 -> 410
C20: CART AWAY AND FILLING
B21: I | C21: Load from spoil heaps and and spread on site, compact levelled murram in 150mm thick layers to the Engineer's satisfaction cart away excavated material from site. | D21: 1408 | E21: CM | F21: 2.2 | G21: =D21*F21 -> 3097.6
B22: J | C22: Load from spoil heaps and remove surplus excavated materials from site | D22: 5636 | E22: CM | F22: 4.1 | G22: =D22*F22 -> 23107.6
C24: TO SUMMARY | G24: =SUM(G9:G23) -> 44573.38
C25: 2/1/1
C26: =C3 -> #REF!
C27: =C4 -> APARTMENTS BLOCK
C28: ELEMENT NO.2
C29: RETAINING WALL
B30: A | C30: Allow for maintaining and upholding sides of excavation : clear off all fallen material, rubbish. | D30: 1 | E30: ITEM | F30: INCLUDED
B31: B | C31: Allow for keeping the whole of the excavation free from general water. | D31: 1 | E31: ITEM | F31: INCLUDED
B32: C | C32: Excavate for retaining wall commencing at reduced level but not exceeding 1.5m deep. | D32: 74 | E32: CM | F32: 1.65 | G32: =F32*D32 -> 122.1
B33: D | C33: Extra over excavation for excavating in rock. | D33: 7 | E33: CM | F33: 6.85 | G33: =F33*D33 -> 47.95
B34: E | C34: Return fill and ram selected excavated material around foundations. | D34: 33 | E34: CM | F34: 2.2 | G34: =F34*D34 -> 72.6
B35: F | C35: Load and remove from site surplus excavated materials | D35: 40 | E35: CM | F35: 3.3 | G35: =F35*D35 -> 132
B36: G | C36: Insecticide treatment to bottom of excavation. | D36: 74 | E36: SM | F36: 1.37 | G36: =F36*D36 -> 101.38
C37: CONCRETE WORK
C38: PLAIN CONCRETE CLASS 15 (15Mpa/19mm concrete with 20mm max. aggregate size)
B39: H | C39: 50mm thick blinding layer under retaining wall footings | D39: =D36 -> 74 | E39: SM | F39: 7.25 | G39: =F39*D39 -> 536.5
C40: VIBRATED REINFORCED CONCRETE CLASS 25 (25Mpa/19mm with 20mm max. aggregate size)
B41: I | C41: Retaining wall footings | D41: 26 | E41: CM | F41: 165 | G41: =F41*D41 -> 4290
B42: J | C42: 200mm thick retaining walls | D42: 188 | E42: SM | F42: 33 | G42: =F42*D42 -> 6204
...

Sheet Fly Sht. Bill No.4
B2: BILL NO.4
B3: ELECTRICAL INSTALLATIONS

Sheet Sum. Bill No.4
B2: ELEMENT | C2: DESCRIPTION | D2: PAGE NO. | E2: AMOUNT (USHS)
C4: ='Fly Sht. Bill No.4'!B2 -> BILL NO.4
C5: ='Fly Sht. Bill No.4'!B3 -> ELECTRICAL INSTALLATIONS
C6: SUMMARY
B7: 1 | C7: LOWER GROUND FLOOR | D7: ='Bill No.4 Electrical Inst.'!C39 -> 4/1/2 | E7: ='Bill No.4 Electrical Inst.'!G38 -> 7461450
B8: 1 | C8: UPPER GROUND FLOOR | D8: ='Bill No.4 Electrical Inst.'!C105 -> 4/2/2 | E8: ='Bill No.4 Electrical Inst.'!G104 -> 60324150
B9: 2 | C9: FIRST FLOOR | D9: ='Bill No.4 Electrical Inst.'!C168 -> 4/3/3 | E9: ='Bill No.4 Electrical Inst.'!G167 -> 89689250
B10: 3 | C10: SECOND FLOOR | D10: ='Bill No.4 Electrical Inst.'!C233 -> 4/4/3 | E10: ='Bill No.4 Electrical Inst.'!G232 -> 94398800
B11: 4 | C11: THIRD FLOOR | D11: ='Bill No.4 Electrical Inst.'!C297 -> 4/5/3 | E11: ='Bill No.4 Electrical Inst.'!G296 -> 88541250
B12: 5 | C12: FOURTH FLOOR | E12: ='Bill No.4 Electrical Inst.'!G360 -> 88541250
B13: 6 | C13: FIFTH FLOOR | E13: ='Bill No.4 Electrical Inst.'!G424 -> 88541250
B14: 7 | C14: ROOF LEVEL | D14: ='Bill No.4 Electrical Inst.'!C463 -> 4/6/2 | E14: ='Bill No.4 Electrical Inst.'!G462 -> 8191600
B15: 8 | C15: MISCELLANEOUS | D15: ='Bill No.4 Electrical Inst.'!C504 -> 4/6/2 | E15: ='Bill No.4 Electrical Inst.'!G503 -> 49848600
B16: 9 | C16: POWER SUPPLY & SWITCHGEAR | D16: ='Bill No.4 Electrical Inst.'!C542 -> 4/7/1 | E16: ='Bill No.4 Electrical Inst.'!G541 -> 280824000
B17: 10 | C17: CABLING | D17: ='Bill No.4 Electrical Inst.'!C599 -> 4/8/3 | E17: ='Bill No.4 Electrical Inst.'!G598 -> 83745000
B18: 11 | C18: STANDBY GENERATOR | D18: ='Bill No.4 Electrical Inst.'!C632 -> 4/9/1 | E18: ='Bill No.4 Electrical Inst.'!G631 -> 160125000
B19: 12 | C19: PV SOLAR SYSTEM | D19: ='Bill No.4 Electrical Inst.'!C671 -> 4/10/1 | E19: ='Bill No.4 Electrical Inst.'!G670 -> 75850000
C27: TOTAL BILL NO.4 CARRIED TO MAIN SUMMARY | E27: =SUM(E8:E26) -> 1168620150
C28: 4/S

Sheet Bill No.4 Electrical Inst.
B2: ITEM | C2: DESCRIPTION | D2: QTY | E2: UNIT | F2: RATE (USHS) | G2: AMOUNT (USHS.)
C3: ='Fly Sht. Bill No.4'!B2 -> BILL NO.4
C4: ='Fly Sht. Bill No.4'!B3 -> ELECTRICAL INSTALLATIONS
C5: ELEMENT NO.1
C6: LOWER GROUND FLOOR
C7: ALL SPECIFIED MATERIALS - GENERAL NOTES
C8: Provide all materials, install, connect and set to work the following all as described in the Specifications and Drawings.
C9: All builder's work required for installation shall be provided for in the prices whether or not specifically measured on described below such shall included all chases, mortices, holes, notches, cutting, plugging making good finishes, painting or repainting etc
B10: A | C10: Lighting points wired by 3x1.5mm2 SC PVC copper cables in 25mm heavy gauge PVC conduit surface/concealed conduit with drops concealed in walls to switch positions complete with MK steel boxes and all accessories. | D10: =SUM(D21:D26) -> 13 | E10: NO | F10: 139050 | G10: =F10*D10 -> 1807650
B11: B | C11: Socket outlet points wired as a ring by 3 x 2.5mm2 SC PVC copper cables in 25mm heavy gauge PVC surface/concealed conduit/trunking complete with boxes for sockets on trunking and all accessories. | D11: 10 | E11: NO | F11: 115850 | G11: =F11*D11 -> 1158500
B12: C | C12: Television outlet points in 25mm heavy gauge PVC conduit concealed in walls complete with MK steel boxes and all accessories. | D12: 1 | E12: NO | F12: 26400 | G12: =F12*D12 -> 26400
B13: D | C13: Fire Alarm points in 25mm heavy gauge PVC surface/concealed conduit complete with all accessories. | D13: 6 | E13: NO | F13: 26400 | G13: =F13*D13 -> 158400
B14: E | C14: CCTV points in 25mm heavy gauge PVC concealed conduit/trunking complete with all accessories. | D14: 2 | E14: NO | F14: 26400 | G14: =F14*D14 -> 52800
B15: G | C15: Public address points in 25mm heavy gauge PVC concealed conduit/trunking complete with all accessories. | D15: 2 | E15: NO | F15: 26400 | G15: =F15*D15 -> 52800
B16: J | C16: Place 50mm diameter PVC pipe sleeves in beams for passing conduits to the Structural Engineer's approval. | D16: 6 | E16: NO | F16: 4950 | G16: =F16*D16 -> 29700
B17: A | C17: Place 100mm diameter PVC pipes in beams for passing AC pipes to the Structural Engineer's approval. | D17: 6 | E17: NO | F17: 6600 | G17: =F17*D17 -> 39600
B18: B | C18: Steel cable tray 600x50mm fixed in cable duct complete with all accessories. | D18: 6 | E18: LM | F18: 148900 | G18: =F18*D18 -> 893400
B19: C | C19: Steel cable tray 300x50mm fixed in cable duct complete with all accessories. | D19: 6 | E19: LM | F19: 99300 | G19: =F19*D19 -> 595800
C20: Lighting Fittings
B21: D | C21: Recessed downlight 15W LED Lamp, 180mm diameter to IP22, complete with DALI Interface as made by Philips or equal approved (Light Type A) | D21: 4 | E21: NO | F21: 87500 | G21: =F21*D21 -> 350000
B22: E | C22: Recessed downlight 15W LED Lamp, 180mm diameter to IP22, complete with emergency unit for 3hours with DALI Interface as made by Philips or equal approved (Light Type AE) | D22: 2 | E22: NO | F22: 134800 | G22: =F22*D22 -> 269600
B23: J | C23: High performance LED 40W recessed modular flat panel 600x600mm, with DALI Interface as made by Philips or equal approved. (Light Type F4) | D23: 3 | E23: NO | F23: 302700 | G23: =F23*D23 -> 908100
B24: K | C24: High performance LED 40W recessed modular flat panel 600x600mm, complete with emergency unit for 3hours with DALI Interface as made by Philips or equal approved. (Light Type F4E) | D24: 1 | E24: NO | F24: 397200 | G24: =F24*D24 -> 397200
B25: F | C25: Ultra-slim white aluminium bodied maintained LED ceiling mounted Emergency EXIT sign, with engraved fire retardant acrylic sign blade, suitable for double sided viewing, with with DALI Interface and 3hour maintained format, to IP20 protection, as Philips or equal approved (Light Type EXIT) | D25: 1 | E25: NO | F25: 85100 | G25: =F25*D25 -> 85100
B26: M | C26: Die-cast aluminium bulkhead with 6W LED lamp and polycarbonate bowl retained by tamper resistant fixings to IP44 as Philips or equal approoved. (Light Type G) For Lift Shaft. | D26: 2 | E26: NO | F26: 106400 | G26: =F26*D26 -> 212800
C27: Light Switches
B28: Q | C28: 6A 1 gang 1 way light switch as CHINT or equal approved complete with all accessories. | D28: 2 | E28: NO | F28: 19850 | G28: =F28*D28 -> 39700
B29: A | C29: 6A 1 gang 2way light switch as CHINT or equal approved complete with all accessories. | D29: 2 | E29: NO | F29: 26450 | G29: =F29*D29 -> 52900
C30: SOCKETS
B31: C | C31: 13A 3pin twin switched socket outlets on wall/trunking as CHINT or equal approved. | D31: 10 | E31: NO | F31: 33100 | G31: =F31*D31 -> 331000
C38: TO SUMMARY | G38: =SUM(G10:G31) -> 7461450
C39: 4/1/2
C40: =C3 -> BILL NO.4
C41: =C4 -> ELECTRICAL INSTALLATIONS
C42: ELEMENT NO.2
C43: UPPER GROUND FLOOR
C44: ALL SPECIFIED MATERIALS - GENERAL NOTES
C45: Provide all materials, install, connect and set to work the following all as described in the Specifications and Drawings.
C46: All builder's work required for installation shall be provided for in the prices whether or not specifically measured on described below such shall included all chases, mortices, holes, notches, cutting, plugging making good finishes, painting or repainting etc
B47: A | C47: Lighting points wired by 3x1.5mm2 SC PVC copper cables in 25mm heavy gauge PVC conduit surface/concealed conduit with drops concealed in walls to switch positions complete with MK steel boxes and all accessories. | D47: =SUM(D78:D90) -> 122 | E47: NO | F47: 139050 | G47: =F47*D47 -> 16964100
...

Sheet Fly Sht. Bill No.5
B2: BILL NO.5
B3: MECHANICAL INSTALLATIONS

Sheet Sum. Bill No.5
B2: ELEMENT | C2: DESCRIPTION | D2: PAGE NO. | E2: AMOUNT (USHS)
C4: ='Fly Sht. Bill No.5'!B2 -> BILL NO.5
C5: ='Fly Sht. Bill No.5'!B3 -> MECHANICAL INSTALLATIONS
C6: SUMMARY
B7: 1 | C7: GROUND FLOOR | D7: ='Bill No.5 Mechanical Inst.'!C72 -> 5/1/3 | E7: ='Bill No.5 Mechanical Inst.'!G71 -> 62234200
B8: 2 | C8: FIRST FLOOR | D8: ='Bill No.5 Mechanical Inst.'!C148 -> 5/2/3 | E8: ='Bill No.5 Mechanical Inst.'!G147 -> 66296800
B9: 3 | C9: SECOND FLOOR | D9: ='Bill No.5 Mechanical Inst.'!C227 -> 5/3/3 | E9: ='Bill No.5 Mechanical Inst.'!G226 -> 60496300
B10: 4 | C10: THIRD FLOOR | D10: ='Bill No.5 Mechanical Inst.'!C303 -> 5/4/3 | E10: ='Bill No.5 Mechanical Inst.'!G302 -> 66339600
B11: 6 | C11: FOURTH FLOOR | E11: ='Bill No.5 Mechanical Inst.'!G378 -> 66339600
B12: 7 | C12: FIFTH FLOOR | E12: ='Bill No.5 Mechanical Inst.'!G429 -> 73357800
B13: 8 | C13: WATER SUPPLY | D13: ='Bill No.5 Mechanical Inst.'!C453 -> 5/6/1 | E13: ='Bill No.5 Mechanical Inst.'!G452 -> 150500000
B14: 9 | C14: SEWER SYSTEM | D14: ='Bill No.5 Mechanical Inst.'!C470 -> 5/7/1 | E14: ='Bill No.5 Mechanical Inst.'!G469 -> 66879000
B15: 810 | C15: STORMWATER DISPOSAL | D15: ='Bill No.5 Mechanical Inst.'!C492 -> 5/8/1 | E15: ='Bill No.5 Mechanical Inst.'!G491 -> 40088800
C26: TOTAL BILL NO.5 CARRIED TO MAIN SUMMARY | E26: =SUM(E7:E25) -> 652532100
C27: 5/S

Sheet Bill No.5 Mechanical Inst.
B2: ITEM | C2: DESCRIPTION | D2: QTY | E2: UNIT | F2: RATE (USHS) | G2: AMOUNT (USHS.)
C3: BILL NO.5
C4: MECHANICAL INSTALLATIONS
C5: ELEMENT NO.1
C6: UPPER GROUND FLOOR
C7: Provide all materials, install, connect and set to work the following all as described in the Specifications and Drawings.
C8: All builder's work required for installation shall be provided for in the prices whether or not specifically measured on described below such shall included all chases, mortices, holes, notches, cutting, plugging making good finishes, painting or repainting etc
C9: Sanitary Fittings
B10: A | C10: "Roca Victoria " BTW WC pan for flush valve, white colour, vitreous china to BS3402 with horizontal outlet complete with WC pan with fixing kit and WC inlet connector, removable plastic seat and cover with self closing system. | D10: 10 | E10: NO | F10: 678700 | G10: =F10*D10 -> 6787000
B11: B | C11: Concealed Flush valve for above WC Pan as DOCOL 1-1/4" back entry type, with integral vacuum break, non-hold-open feature and non-return valve, inlet control stop and wall plate complete with all accessories, as DOCOL or equal approved. | D11: 10 | E11: NO | F11: 595900 | G11: =F11*D11 -> 5959000
B12: C | C12: 530x450mm Countertop Vitreous China Wash Hand Basin, with one tap hole 38mm chrome plated chain waste, plastic bottle trap, complete with all accessories as Ideal Standard tempo 53 or equal approved. | D12: 8 | E12: NO | F12: 678700 | G12: =F12*D12 -> 5429600
B13: D | C13: Hands free electronic control pillar tap, single temperature 1/2" BSP F1 complete with pillar tap, mounting kit, solenoid valve as Cobratron EL-JOE by COBRA. | D13: 8 | E13: NO | F13: 347600 | G13: =F13*D13 -> 2780800
B14: E | C14: Mains power supply for electronic tap as EL-Trans Cobratron Transformer 10 Channel mains power supply unit, 220V AC to 9V DC | D14: 8 | E14: NO | F14: 264800 | G14: =F14*D14 -> 2118400
B15: F | C15: Vitreous China semi-recessed toilet roll holder complete with fixing to the wall as Armitage Shanks Mayfair S5009 or equal approved. | D15: 12 | E15: NO | F15: 82700 | G15: =F15*D15 -> 992400
B16: G | C16: Vitreous China Urinal Bowl complete with 38mm chrome plated waste, for flush valve fittings complete with all accessories, as Armitage Shanks Contour S6110 or equal approved. | D16: 4 | E16: NO | F16: 314500 | G16: =F16*D16 -> 1258000
B17: H | C17: Urinal proximity sensor surface mounted complete with solenoid, combined servicing valve and filter, float switch with 10metre extension cable and all accessories as Armitage Shanks Urinal proximity sensor S8116 or equal approved. | D17: 4 | E17: NO | F17: 331000 | G17: =F17*D17 -> 1324000
B18: A | C18: Vitreous China Urinal Bowl separator complete with all accessories, as Armitage Shanks S6120 or equal approved. | D18: 2 | E18: NO | F18: 198600 | G18: =F18*D18 -> 397200
B19: B | C19: 6mm glass plate mirror size 610x475mm with bevelled edges complete. | D19: 8 | E19: NO | F19: 82700 | G19: =F19*D19 -> 661600
B20: C | C20: PWD Suite with Vitreous China low level, with 6no Grab rails in powder coated aluminium and P outlet 6 litre cistern, valve fittings complete with seat and cover and all accessories, with washbasin and non-concussive tap, bottle trap and all accessories as Armitage Shanks Standard Pack S687501 or equal approved. | D20: 2 | E20: NO | F20: 5959450 | G20: =F20*D20 -> 11918900
B21: D | C21: Cleaner's sink in fireclay 510x380mm with splash back, grating complete with Nimbus bib tap and all accessories as Armitage Shanks Alder S5900 or equal approved.. | D21: 2 | E21: NO | F21: 1059450 | G21: =F21*D21 -> 2118900
... B23: F | C23: Pressure type under sink water heater 35litres with glass lining complete with all accessories as Ariston or equal approved for Kitchen. | D23: 2 | E23: NO | F23: 645600 | G23: =F23*D23 -> 1291200
C24: Internal Plumbing
C25: All pipe work shall be PPR PN25, all diameters below are outer diameter and shall be complete with fittings such as bends elbows, tees and all accessories and shall be inclusive of all builder's work.
B26: G | C26: 100mm Pipe work complete. | D26: 8 | E26: LM | F26: 115800 | G26: =F26*D26 -> 926400
B27: H | C27: 100x50mm saddle clamp complete | D27: 2 | E27: NO | F27: 43000 | G27: =F27*D27 -> 86000
B28: I | C28: 80mm Pipe work complete. | D28: 12 | E28: LM | F28: 43000 | G28: =F28*D28 -> 516000
B29: J | C29: 65mm Pipe work complete. | D29: 12 | E29: LM | F29: 36400 | G29: =F29*D29 -> 436800
B30: K | C30: 50mm Pipe work complete. | D30: 48 | E30: LM | F30: 43000 | G30: =F30*D30 -> 2064000
B31: L | C31: 40mm Pipe work complete. | D31: 60 | E31: LM | F31: 36400 | G31: =F31*D31 -> 2184000
B32: M | C32: 32mm Pipe work complete. | D32: 54 | E32: LM | F32: 29700 | G32: =F32*D32 -> 1603800
B33: N | C33: 25mm Pipe work complete. | D33: 48 | E33: LM | F33: 23100 | G33: =F33*D33 -> 1108800
B34: O | C34: 20mm Pipe work complete. | D34: 60 | E34: LM | F34: 13200 | G34: =F34*D34 -> 792000
B35: P | C35: 80mm globe valves | D35: 2 | E35: NO | F35: 165500 | G35: =F35*D35 -> 331000
B36: Q | C36: 65mm globe valves | D36: 2 | E36: NO | F36: 109250 | G36: =F36*D36 -> 218500
B37: R | C37: 50mm globe valves | D37: 4 | E37: NO | F37: 165500 | G37: =F37*D37 -> 662000
... B42: A | C42: 13mm stainless steel braided tubing 300mm long including unions and jointing to steel pipes. | D42: 20 | E42: NO | F42: 16550 | G42: =F42*D42 -> 331000
C43: Foul Water
C44: Supply and fix the following in PVC soil and waste system to BS 4514 with fittings, fixed according to the manufacturer's printed instructions and BS 5572:1978 all as supplied by KEY-TERRAIN or equal, complete with all fittings and accessories.
B45: B | C45: 160mm PVC soil waste pipe on wall and or in duct. | D45: 18 | E45: LM | F45: 82700 | G45: =F45*D45 -> 1488600
B46: C | C46: 110m PVC soil waste pipe on wall and or in duct. | D46: 28 | E46: LM | F46: 59500 | G46: =F46*D46 -> 1666000
...

Sheet Fly Sht. Bill No.6
B2: BILL NO.6
B3: FIRE FIGHTING INSTALLATIONS

Sheet Sum. Bill No.6
B2: ELEMENT | C2: DESCRIPTION | D2: PAGE NO. | E2: AMOUNT (USHS)
C4: ='Fly Sht. Bill No.6'!B2 -> BILL NO.6
C5: ='Fly Sht. Bill No.6'!B3 -> FIRE FIGHTING INSTALLATIONS
C6: SUMMARY
B7: 1 | C7: ='Bill No.6 Fire fighting Inst.'!C8 -> UPPER GROUND FLOOR | D7: ='Bill No.6 Fire fighting Inst.'!C35 -> 6/1/2 | E7: ='Bill No.6 Fire fighting Inst.'!G34 -> 38979500
B8: 2 | C8: ='Bill No.6 Fire fighting Inst.'!C39 -> FIRST FLOOR | D8: ='Bill No.6 Fire fighting Inst.'!C64 -> 6/2/1 | E8: ='Bill No.6 Fire fighting Inst.'!G63 -> 38979500
B9: 3 | C9: ='Bill No.6 Fire fighting Inst.'!C68 -> SECOND FLOOR | D9: ='Bill No.6 Fire fighting Inst.'!C93 -> 6/3/1 | E9: ='Bill No.6 Fire fighting Inst.'!G92 -> 38979500
B10: 4 | C10: ='Bill No.6 Fire fighting Inst.'!C97 -> THIRD FLOOR | D10: ='Bill No.6 Fire fighting Inst.'!C122 -> 6/4/1 | E10: ='Bill No.6 Fire fighting Inst.'!G121 -> 38979500
C11: FOURTH FLOOR | E11: ='Bill No.6 Fire fighting Inst.'!G150 -> 38979500
C12: FIFTH FLOOR | E12: ='Bill No.6 Fire fighting Inst.'!G179 -> 38979500
B13: 5 | C13: ='Bill No.6 Fire fighting Inst.'!C184 -> ROOF | D13: ='Bill No.6 Fire fighting Inst.'!C205 -> 6/5/1 | E13: ='Bill No.6 Fire fighting Inst.'!G204 -> 8442000
B14: 6 | C14: ='Bill No.6 Fire fighting Inst.'!C209 -> FIRE FIGHTING EQUIPMENT | D14: ='Bill No.6 Fire fighting Inst.'!C250 -> 6/6/1 | E14: ='Bill No.6 Fire fighting Inst.'!G249 -> 119320000
B15: 7 | C15: ='Bill No.6 Fire fighting Inst.'!C254 -> MISCELLANEOUS | D15: ='Bill No.6 Fire fighting Inst.'!C322 -> 6/7/1 | E15: ='Bill No.6 Fire fighting Inst.'!G321 -> 33832000
C26: TOTAL BILL NO.6 CARRIED TO MAIN SUMMARY | E26: =SUM(E7:E25) -> 395471000
C27: 6/S

Sheet Bill No.6 Fire fighting Inst.
B2: ITEM | C2: DESCRIPTION | D2: QTY | E2: UNIT | F2: RATE (USHS) | G2: AMOUNT (USHS.)
C3: BILL NO.6
C4: FIRE FIGHTING INSTALLATIONS
C5: Provide all materials, install, connect and set to work the following all as described in the Specifications and Drawings.
C6: All builder's work required for installation shall be provided for in the prices whether or not specifically measured on described below such shall included all chases, mortices, holes, notches, cutting, plugging making good finishes, painting or repainting etc
C7: ELEMENT NO.1
C8: UPPER GROUND FLOOR
C9: Fire Fighting Installations
C10: Portable Fire Extinguishers
B11: A | C11: Carbon Dioxide portable fire extinguisher 5kg as NAFFCO CO2 gas extinguisher Model NC5 or equal approved. | D11: 2 | E11: NO | F11: 280000 | G11: =F11*D11 -> 560000
B12: B | C12: Dry powder portable fire extinguisher 9 kg as NAFFCO ABC powder Model NP9 or equal approved. | D12: 2 | E12: NO | F12: 262500 | G12: =F12*D12 -> 525000
C13: Hose Reel Installations | F13: 0 | G13: =F13*D13 -> 0
B14: C | C14: 75mm Black Seamless Steel SCH40 pipe from water tank to hose reels complete with all accessories. | D14: 6 | E14: LM | F14: 192500 | G14: =F14*D14 -> 1155000
B15: D | C15: 75x32x75mm Tee Black Seamless Steel SCH40 | D15: 2 | E15: NO | F15: 87500 | G15: =F15*D15 -> 175000
B16: E | C16: 750x505mm Reducer Black Seamless Steel SCH40 | D16: 2 | E16: NO | F16: 63000 | G16: =F16*D16 -> 126000
B17: F | C17: 50mm globe valves | D17: 2 | E17: NO | F17: 227500 | G17: =F17*D17 -> 455000
B18: G | C18: 25mm Black Seamless Steel SCH40 pipe complete with all accessories. | D18: 12 | E18: LM | F18: 19250 | G18: =F18*D18 -> 231000
B19: H | C19: Swinging arm automatic semi-rigid hose reel 19mm diameter and 30m long to BSEN 671-1-2001 and BSEN 694-2001 complete with all accessories including wall mounting box, Jet and Spray nozzle and all accessories as NAFFCO Model 19NFH-020A or equal approved. | D19: 2 | E19: NO | F19: 1225000 | G19: =F19*D19 -> 2450000
C20: SPRINKLER SYSTEM
B21: I | C21: 100mm Black Seamless Steel SCH40 pipe complete with all accessories. | D21: 12 | E21: LM | F21: 227500 | G21: =F21*D21 -> 2730000
B22: J | C22: 75mm Black Seamless Steel SCH40 pipe complete with all accessories. | D22: 45 | E22: LM | F22: 192500 | G22: =F22*D22 -> 8662500
B23: K | C23: 65mm Black Seamless Steel SCH40 pipe complete with all accessories. | D23: 6 | E23: LM | F23: 140000 | G23: =F23*D23 -> 840000
B24: L | C24: 50mm Black Seamless Steel SCH40 pipe complete with all accessories. | D24: 24 | E24: LM | F24: 105000 | G24: =F24*D24 -> 2520000
B25: M | C25: 40mm Black Seamless Steel SCH40 pipe complete with all accessories. | D25: 48 | E25: LM | F25: 98000 | G25: =F25*D25 -> 4704000
B26: N | C26: 32mm Black Seamless Steel SCH40 pipe complete with all accessories. | D26: 90 | E26: LM | F26: 84000 | G26: =F26*D26 -> 7560000
B27: A | C27: 100x75mm Reducer Black Seamless Steel SCH40 | D27: 4 | E27: NO | F27: 122500 | G27: =F27*D27 -> 490000
B28: B | C28: 50x50x15mm Tee Black Seamless Steel SCH40 | D28: 60 | E28: NO | F28: 7000 | G28: =F28*D28 -> 420000
B29: C | C29: 75mm Globe Valve | D29: 4 | E29: NO | F29: 490000 | G29: =F29*D29 -> 1960000
B30: D | C30: 50mm globe valves | D30: 8 | E30: NO | F30: 252000 | G30: =F30*D30 -> 2016000
B31: E | C31: Sprinkler heads 78 deg C resistant | D31: 40 | E31: NO | F31: 35000 | G31: =F31*D31 -> 1400000
C34: TO SUMMARY | G34: =SUM(G11:G32) -> 38979500
C35: 6/1/2
C36: BILL NO.6
C37: FIRE FIGHTING INSTALLATIONS
C38: ELEMENT NO.2
C39: FIRST FLOOR
C40: Fire Fighting Installations
C41: Portable Fire Extinguishers
B42: A | C42: Carbon Dioxide portable fire extinguisher 5kg as NAFFCO CO2 gas extinguisher Model NC5 or equal approved. | D42: 2 | E42: NO | F42: 280000 | G42: =F42*D42 -> 560000
B43: B | C43: Dry powder portable fire extinguisher 9 kg as NAFFCO ABC powder Model NP9 or equal approved. | D43: 2 | E43: NO | F43: 262500 | G43: =F43*D43 -> 525000
...

Sheet Fly Sht. Bill No.7
B2: BILL NO.7
B3: HVAC INSTALLATIONS

Sheet Sum. Bill No.7
B2: ELEMENT | C2: DESCRIPTION | D2: PAGE NO. | E2: AMOUNT (USHS)
C4: ='Fly Sht. Bill No.7'!B2 -> BILL NO.7
C5: ='Fly Sht. Bill No.7'!B3 -> HVAC INSTALLATIONS
C6: SUMMARY
B7: 1 | C7: CONFERENCE HALL | D7: =#REF! -> #REF! | E7: ='Bill No 7 HVAC'!F93 -> 1.5417343e+08
B8: 2 | C8: UPPER GROUND FLOOR | D8: =#REF! -> #REF! | E8: ='Bill No 7 HVAC'!F181 -> 1.3362899e+08
B9: 3 | C9: FIRST FLOOR | D9: =#REF! -> #REF! | E9: ='Bill No 7 HVAC'!F263 -> 1.4855891e+08
B10: 4 | C10: SECOND FLOOR | D10: =#REF! -> #REF! | E10: ='Bill No 7 HVAC'!F330 -> 1.5691649e+08
B11: 6 | C11: THIRD FLOOR | D11: =#REF! -> #REF! | E11: ='Bill No 7 HVAC'!F421 -> 2.2379258e+08
B12: 7 | C12: FOURTH FLOOR | E12: ='Bill No 7 HVAC'!F515 -> 2.2379258e+08
B13: 8 | C13: FIFTH FLOOR | E13: ='Bill No 7 HVAC'!F598 -> 2.2379258e+08
C24: TOTAL BILL NO.7 CARRIED TO MAIN SUMMARY | E24: =SUM(E7:E23) -> 1.2646556e+09
C25: 7/S

Sheet Bill No 7 HVAC
B1: BILLS OF QUANTITIES
A2: Item | B2: Description | C2: Unit | D2: Total Qty | E2: Rate (UGX) | F2: Amount (UGX)
B3: AIR CONDITIONING & VENTILATION
B4: CONFERENCE ROOM
B5: INDOOR UNITS VRF SYSTEM
B6: CEILING CONCEALED DUCT TYPE
B7: Supply Installation Testing and Commissioning of Ceiling Concelead duct type indoor units having
B8: galvanized steel plate casing. The unit shall be insulated with sound absorbing thermal insulation material.
B9: The unit shall be supplied with drain pump with micro processor control.
B10: CEILING CONCEALED DUCT TYPE
A11: A | B11: 14.1kW (48,000Btu/hr) Model: ARNU48GM3A4 CEILING CONCELEAD DUCT AC UNITS | C11: No | D11: 6 | E11: 4100908.5 | F11: =D11*E11 -> 24605451
A12: B | B12: Supply and Installation of Corded remotes with LCD Desplay for VRF indoor units | C12: No | D12: 6 | E12: 360677.97 | F12: =D12*E12 -> 2164067.8
B13: OUTDOOR UNITS OF VRF SYSTEM
B14: Supply Installation Testing and Commissioning of Compact Air Cooled type outdoor units of VRF System
B15: having hermetically sealed scroll type compressors, Dual sensing control and ocean black fin heat exchanger
B16: The unit shall be provided with its own microprocessor control panel with provision for integration with the
B17: building management system for Air-conditioning system.
B18: The VRF System shall have green ref. gas R410A
A19: A | B19: Condensing unit of total cooling coil design capacity 33.6kW, ARUN120LLS5, Input: 8.9kw (3Ph 400V 50Hz). | C19: No | D19: 1 | E19: 23584217 | F19: =D19*E19 -> 23584217
A20: B | B20: Condensing unit of total cooling coil design capacity 56kW, ARUN200LLS5, Input: 14.1kw (3Ph 400V 50Hz). | C20: No | D20: 1 | E20: 27998915 | F20: =D20*E20 -> 27998915
B21: VRV SYSTEM ACCESSORIES
B22: BRANCH DISTRIBUTION REFRIGERENT PIPE JOINTS WITH PRECAST INSULATION
A23: i | B23: ARBLN03321 | C23: No | D23: 2 | E23: 346250.85 | F23: =D23*E23 -> 692501.7
A24: ii | B24: ARBLN07121 | C24: No | D24: 2 | E24: 555444.06 | F24: =D24*E24 -> 1110888.1
A25: iii) | B25: ARBLN14521 | C25: No | D25: 1 | E25: 692501.7 | F25: =D25*E25 -> 692501.7
A26: iv) | B26: ARCNN21 | C26: No | D26: 1 | E26: 483308.47 | F26: =D26*E26 -> 483308.47
B27: REFRIGERATION PIPING & FIRST CHARGE OF REFRIGERANT FOR VRV SYSTEM
A28: i | B28: 9.52mm | C28: LM | D28: 80 | E28: 36480 | F28: =D28*E28 -> 2918400
A29: C | B29: 12.7mm | C29: LM | D29: 5 | E29: 42560 | F29: =D29*E29 -> 212800
A30: ii | B30: 15.88mm | C30: LM | D30: 85 | E30: 54720 | F30: =D30*E30 -> 4651200
A31: iii) | B31: 19.05mm | C31: LM | D31: 25 | E31: 76000 | F31: =D31*E31 -> 1900000
A32: iv) | B32: 22.2mm | C32: LM | D32: 20 | E32: 88160 | F32: =D32*E32 -> 1763200
A33: H | B33: 28.58mm | C33: LM | D33: 10 | E33: 115520 | F33: =D33*E33 -> 1155200
A34: J | B34: 34.9mm | C34: LM | D34: 30 | E34: 173888 | F34: =D34*E34 -> 5216640
B35: Refrigerant
A36: a | B36: Additional Refrigerant of R410A | C36: kg | D36: 20 | E36: 115520 | F36: =D36*E36 -> 2310400
A37: b | B37: Power Cabling to individual Outdoor units with PVC conduits. ( From Isolator to VRV ODU within 5m , The size of the | C37: LM | D37: 10 | E37: 91200 | F37: =D37*E37 -> 912000
B38: cable shall be as per manufacurer's technical requirement )
A39: c | B39: Communication Cable between Outdoor Units & Indoor Units with PVC conduits ( The size of the control cable shall be | C39: LM | D39: 255 | E39: 6779.664 | F39: =D39*E39 -> 1728814.3
B40: as per manufacturer's technical requirement )
...

Sheet Fly Sht. Bill No.8
B2: BILL NO.8
B3: LIFT INSTALLATIONS

Sheet Bill No.8 Lift Inst.
B2: ITEM | C2: DESCRIPTION | D2: QTY | E2: UNIT | F2: RATE (USHS) | G2: AMOUNT (USHS.)
C3: BILL NO.8
C4: LIFT INSTALLATIONS
C5: Provide all materials, install, connect and set to work the following all as described in the Specifications and Drawings.
C6: All builder's work required for installation shall be provided for in the prices whether or not specifically measured on described below such shall included all chases, mortices, holes, notches, cutting, plugging making good finishes, painting or repainting etc
C7: ORDINARY PASSENGER LIFTS
C8: The Contractor will inspect site, study drawings, and supply, install, test and commission to the satisfaction of the Engineer, lifts with the following specific details:-
C9: Discrepancies between drawings and specifications must be brought to the attention of the Engineer before supplying the equipment.
C10: The Contractor shall therefore be responsible for supply and installation of a fully operational lift with a certificate from the Government Lift Inspector and a warranty from the manufacturers of at least 1 year.
C11: The lift control shall include an automatic rescue device which shall in case of power failure move the lift car to the next landing and automatically open the doors.
C12: The lift shall be equipped with regenerative braking.
C13: The lift shall be as that made by KONE, or OTIS, or SCHINDLER or MITSUBISHI
C14: The lifts shall include an interface/system/gateway to allow third party to monitor and limited control: Position of lift, up/down, door open/closed, number of persons in lift (overload), VIP reservation of lift, Access Control with Cards, Emergency Stop, Fire etc.
B15: A | C15: Capacity: 1000kg (13 persons). | D15: 2 | E15: NO | F15: 169000000 | G15: =F15*D15 -> 338000000
C16: Number of Stops 7
C17: Number of Opennings 7
C18: Travel: 24 metres (approx.)
C19: Shaft: 2000mm wide by 2300mm deep (inside dimensions)
C20: Drive: Variable Voltage Variable Frequency (VVVF)
C21: Speed: 1.0M/S
C22: Drive: On the side of shaft (machine room-less)
C23: Openings: Double leaf centre telescoping opening, 900mm wide.
C24: Cabin: To be hairline stainless steel
C25: All doors: To be hairline stainless steel
C26: Landing door at Ground floor: In hairline stainless steel
C27: Door architraves: To be in stainless steel
... C31: Power Supply: 415V, 3 phase 50Hz
B32: A | C32: Voltage stabilizer for the lift | D32: 2 | E32: NO | F32: 7350000 | G32: =F32*D32 -> 14700000
B33: B | C33: Builder's works | D33: 2 | E33: ITEM | F33: 1750000 | G33: =F33*D33 -> 3500000
B34: C | C34: Fireman's Switch | D34: 2 | E34: NO | F34: 350000 | G34: =F34*D34 -> 700000
C37: TO SUMMARY | G37: =SUM(G15:G35) -> 356900000
C38: 8/S

Sheet Fly Sht. Bill No.9
B2: BILL NO.9
B3: ICT INSTALLATIONS

Sheet Sum. Bill No.9
B2: ELEMENT | C2: DESCRIPTION | D2: PAGE NO. | E2: AMOUNT (USHS)
C4: ='Fly Sht. Bill No.9'!B2 -> BILL NO.9
C5: ='Fly Sht. Bill No.9'!B3 -> ICT INSTALLATIONS
C6: SUMMARY
B7: 3 | C7: FIRE ALARM SYSTEM | D7: ='Bill No.9 ICT Inst.'!C44 -> 9/3/2 | E7: ='Bill No.9 ICT Inst.'!G43 -> 38685000
B8: 4 | C8: PUBLIC ADDRESS & EVACUATION SYSTEM | D8: ='Bill No.9 ICT Inst.'!C78 -> 9/4/1 | E8: ='Bill No.9 ICT Inst.'!G77 -> 28520000
B9: 5 | C9: AUDIO VISUAL CONFERENCING SYSTEM | D9: ='Bill No.9 ICT Inst.'!C161 -> 9/5/5 | E9: ='Bill No.9 ICT Inst.'!G160 -> 105024000
B10: 6 | C10: SECURITY EQUIPMENT | D10: ='Bill No.9 ICT Inst.'!C195 -> 9/6/1 | E10: ='Bill No.9 ICT Inst.'!G194 -> 8832500
B11: 7 | C11: VOICE & DATA | D11: ='Bill No.9 ICT Inst.'!C236 -> 9/7/3 | E11: ='Bill No.9 ICT Inst.'!G235 -> 150760500
B12: 8 | C12: ACCESS CONTROL | D12: ='Bill No.9 ICT Inst.'!C259 -> 9/8/3 | E12: ='Bill No.9 ICT Inst.'!G258 -> 30635000
B13: 9 | C13: CCTV SYSTEM | D13: ='Bill No.9 ICT Inst.'!C281 -> 9/9/2 | E13: ='Bill No.9 ICT Inst.'!G280 -> 39307500
B14: 10 | C14: IP TV & SIGNAGE SYSTEM | D14: ='Bill No.9 ICT Inst.'!C300 -> 9/10/2 | E14: ='Bill No.9 ICT Inst.'!G299 -> 28502000
C24: TOTAL BILL NO.9 CARRIED TO MAIN SUMMARY | E24: =SUM(E7:E23) -> 430266500
C25: 9/S

Sheet Bill No.9 ICT Inst.
B2: ITEM | C2: DESCRIPTION | D2: QTY | E2: UNIT | F2: RATE (USHS) | G2: AMOUNT (USHS.)
C3: BILL NO.9
C4: ICT INSTALLATIONS
C5: ELEMENT NO.1
C6: Provide all materials, install, connect and set to work the following all as described in the Specifications and Drawings.
C7: All builder's work required for installation shall be provided for in the prices whether or not specifically measured on described below such shall included all chases, mortices, holes, notches, cutting, plugging making good finishes, painting or repainting etc
C8: BILL NO.9
C9: ICT INSTALLATIONS
C10: ELEMENT NO.3
C11: FIRE ALARM SYSTEM
B12: A | C12: 4Loop Analogue addressable Fire Alarm Control Panel Consisting of: | D12: 1 | E12: NO | F12: 6200000 | G12: =F12*D12 -> 6200000
C13: 1 No. Central Processor Unit Module 3-CPU3
C14: 1 No. Network Communications Card, Class A 3-RS485A / MOD-BUS Interface.
C15: 1 No. Liquid Crystal Display Module 3-LCD
C16: 1 No. Primary Power Supply with Local Rail Module, 230V 3-PPS/M-230
C17: 1 No. Single Signature Driver Controller 3-SSDC1
C18: 3 No. Signature Dual Driver Controller 3-SDDC1
C19: 1 No. Chassis Assembly 3-CHAS7
C20: 1 No. Wall box with 1 Chassis Space 3-CAB7B
C21: 1 No. Door for CAB7B Series Wall box 3-CAB7D
C22: 2 No. 40Ah Sealed Lead Acid Battery - 12 Vic 12V40A
C23: 1 No. Battery Cabinet 14" x 18.25"x 7.25" - 40AH max BC-1
C24: 2 No. 6.5 Amp Booster Power Supply BPS6A/230
... C27: Repeater Panel:
B28: B | C28: Repeater Fire Alarm Control Panel each Consists of: | D28: 1 | E28: NO | F28: 1800000 | G28: =F28*D28 -> 1800000
C29: 1 No. Remote LCD Command Module Annunciator 3-LCDANN
C30: 1 No. Surface Wall Box - for Remote LCD Command Module RLCM/B-S
C31: Field Devices:
B32: C | C32: Intelligent Second Generation Photoelectric Smoke Detector SIGA2-PS complete with base and all accessories. | D32: 125 | E32: NO | F32: 105000 | G32: =F32*D32 -> 13125000
B33: D | C33: Intelligent Second Generation Fixed Temperature / Rate-of-Rise Heat Detector - 135F, 15F per minute SIGA2-HRS complete with base and all accessories. | D33: 20 | E33: NO | F33: 145000 | G33: =F33*D33 -> 2900000
B34: E | C34: Manual Pull Station - Double Action, 1-stage (Back Box Not Included) SIGA-278 | D34: 10 | E34: NO | F34: 175000 | G34: =F34*D34 -> 1750000
B35: F | C35: Multi-cd temporal horn-strobe, hi/lo dB - 24V, WHITE G1-HDVM | D35: 10 | E35: NO | F35: 157500 | G35: =F35*D35 -> 1575000
B36: G | C36: Mains Bell | D36: 10 | E36: NO | F36: 210000 | G36: =F36*D36 -> 2100000
B37: H | C37: Signal Input (Riser) Module SIGA-CC1 | D37: 1 | E37: NO | F37: 315000 | G37: =F37*D37 -> 315000
B38: I | C38: Control Relay Module (Interface With Elevators) SIGA-CR | D38: 1 | E38: NO | F38: 210000 | G38: =F38*D38 -> 210000
B39: J | C39: Control Relay Module (Interface With AC) SIGA-CR | D39: 1 | E39: NO | F39: 210000 | G39: =F39*D39 -> 210000
B40: A | C40: Fire Alarm points wired by fire retardant cable 2 core, 1.0mm2 complete with all accessories | D40: =SUM(D12:D39) -> 180 | E40: NO | F40: 35000 | G40: =F40*D40 -> 6300000
B41: B | C41: Programming, Testing, Commissioning, start-up and Handover | D41: 1 | E41: ITEM | F41: 2200000 | G41: =F41*D41 -> 2200000
C43: TO SUMMARY | G43: =SUM(G12:G41) -> 38685000
C44: 9/3/2
...
